[2014-07-17 17:35:44.384794]
ERROR
	Traceback (most recent call last):
[2014-07-17 17:35:44.385040]
ERROR
	  File "appmain.py", line 29, in <module>
[2014-07-17 17:35:44.385160]
ERROR
	    model_default_config=model_default_config, model_config=model_config)
[2014-07-17 17:35:44.385543]
ERROR
	  File "/home/server/PycharmProjects/sphinx/gfirefly/server/server.py", line 116, in config
[2014-07-17 17:35:44.385824]
ERROR
	    __import__(app)
[2014-07-17 17:35:44.385919]
ERROR
	  File "/home/server/PycharmProjects/sphinx/app/accountserver.py", line 8, in <module>
[2014-07-17 17:35:44.386017]
ERROR
	    initapp.load_module()
[2014-07-17 17:35:44.386132]
ERROR
	  File "/home/server/PycharmProjects/sphinx/app/account/initapp.py", line 9, in load_module
[2014-07-17 17:35:44.386293]
ERROR
	    from action.node import account
[2014-07-17 17:35:44.387382]
ERROR
	  File "/home/server/PycharmProjects/sphinx/app/account/action/node/account.py", line 9, in <module>
[2014-07-17 17:35:44.388116]
ERROR
	    from app.account.redis_mode import tb_account
[2014-07-17 17:35:44.388411]
ERROR
	  File "/home/server/PycharmProjects/sphinx/app/account/redis_mode.py", line 10, in <module>
[2014-07-17 17:35:44.388709]
ERROR
	    tb_account.insert()
[2014-07-17 17:35:44.388969]
ERROR
	  File "/home/server/PycharmProjects/sphinx/shared/db_entrust/redis_mode.py", line 176, in insert
[2014-07-17 17:35:44.389339]
ERROR
	    RedisObject.insert(self)
[2014-07-17 17:35:44.389647]
ERROR
	  File "/home/server/PycharmProjects/sphinx/shared/db_entrust/redis_object.py", line 140, in insert
[2014-07-17 17:35:44.390595]
ERROR
	    self._client.mset(newmapping)
[2014-07-17 17:35:44.391085]
ERROR
	  File "build/bdist.linux-x86_64/egg/redis/client.py", line 782, in mset
[2014-07-17 17:35:44.391258]
ERROR
	  File "build/bdist.linux-x86_64/egg/redis/client.py", line 464, in execute_command
[2014-07-17 17:35:44.391443]
ERROR
	  File "build/bdist.linux-x86_64/egg/redis/connection.py", line 334, in send_command
[2014-07-17 17:35:44.391713]
ERROR
	  File "build/bdist.linux-x86_64/egg/redis/connection.py", line 316, in send_packed_command
[2014-07-17 17:35:44.392995]
ERROR
	  File "build/bdist.linux-x86_64/egg/redis/connection.py", line 253, in connect
[2014-07-17 17:35:44.393058]
ERROR
	redis.exceptions.ConnectionError: Error 111 connecting 127.0.0.1:6379. Connection refused.
