[2014-06-23 17:40:10.294245]
ERROR
	Traceback (most recent call last):
[2014-06-23 17:40:10.294818]
ERROR
	  File "appmain.py", line 29, in <module>
[2014-06-23 17:40:10.294893]
ERROR
	    model_default_config=model_default_config, model_config=model_config)
[2014-06-23 17:40:10.294953]
ERROR
	  File "/home/server/PycharmProjects/traversing/gfirefly/server/server.py", line 118, in config
[2014-06-23 17:40:10.295051]
ERROR
	    __import__(app)
[2014-06-23 17:40:10.295119]
ERROR
	  File "/home/server/PycharmProjects/traversing/app/accountserver.py", line 8, in <module>
[2014-06-23 17:40:10.298487]
ERROR
	    initapp.load_module()
[2014-06-23 17:40:10.298586]
ERROR
	  File "/home/server/PycharmProjects/traversing/app/account/initapp.py", line 11, in load_module
[2014-06-23 17:40:10.299131]
ERROR
	    from action.local import account
[2014-06-23 17:40:10.302124]
ERROR
	  File "/home/server/PycharmProjects/traversing/app/account/action/local/account.py", line 7, in <module>
[2014-06-23 17:40:10.310482]
ERROR
	    from app.account.redis_mode import tb_account
[2014-06-23 17:40:10.310588]
ERROR
	  File "/home/server/PycharmProjects/traversing/app/account/redis_mode.py", line 10, in <module>
[2014-06-23 17:40:10.311323]
ERROR
	    tb_account.insert()
[2014-06-23 17:40:10.311403]
ERROR
	  File "/home/server/PycharmProjects/traversing/shared/db_entrust/redis_mode.py", line 169, in insert
[2014-06-23 17:40:10.316375]
ERROR
	    RedisObject.insert(self)
[2014-06-23 17:40:10.316496]
ERROR
	  File "/home/server/PycharmProjects/traversing/shared/db_entrust/redis_object.py", line 138, in insert
[2014-06-23 17:40:10.316976]
ERROR
	    self._client.mset(newmapping)
[2014-06-23 17:40:10.317052]
ERROR
	  File "build/bdist.linux-x86_64/egg/redis/client.py", line 782, in mset
[2014-06-23 17:40:10.317703]
ERROR
	  File "build/bdist.linux-x86_64/egg/redis/client.py", line 464, in execute_command
[2014-06-23 17:40:10.317912]
ERROR
	  File "build/bdist.linux-x86_64/egg/redis/connection.py", line 334, in send_command
[2014-06-23 17:40:10.318179]
ERROR
	  File "build/bdist.linux-x86_64/egg/redis/connection.py", line 316, in send_packed_command
[2014-06-23 17:40:10.318339]
ERROR
	  File "build/bdist.linux-x86_64/egg/redis/connection.py", line 253, in connect
[2014-06-23 17:40:10.318488]
ERROR
	redis.exceptions.ConnectionError: Error 111 connecting 127.0.0.1:6379. Connection refused.
