[2014-07-17 17:35:44.532716]
ERROR
	Traceback (most recent call last):
[2014-07-17 17:35:44.532850]
ERROR
	  File "appmain.py", line 29, in <module>
[2014-07-17 17:35:44.534156]
ERROR
	    model_default_config=model_default_config, model_config=model_config)
[2014-07-17 17:35:44.534367]
ERROR
	  File "/home/server/PycharmProjects/sphinx/gfirefly/server/server.py", line 116, in config
[2014-07-17 17:35:44.534510]
ERROR
	    __import__(app)
[2014-07-17 17:35:44.534724]
ERROR
	  File "/home/server/PycharmProjects/sphinx/app/gateserver.py", line 9, in <module>
[2014-07-17 17:35:44.534856]
ERROR
	    initapp.load_module()
[2014-07-17 17:35:44.534940]
ERROR
	  File "/home/server/PycharmProjects/sphinx/app/gate/initapp.py", line 11, in load_module
[2014-07-17 17:35:44.535023]
ERROR
	    from action.local import login
[2014-07-17 17:35:44.535102]
ERROR
	  File "/home/server/PycharmProjects/sphinx/app/gate/action/local/login.py", line 7, in <module>
[2014-07-17 17:35:44.535182]
ERROR
	    from app.gate.redis_mode import tb_nickname_mapping
[2014-07-17 17:35:44.535352]
ERROR
	  File "/home/server/PycharmProjects/sphinx/app/gate/redis_mode.py", line 10, in <module>
[2014-07-17 17:35:44.535485]
ERROR
	    tb_account.insert()
[2014-07-17 17:35:44.535623]
ERROR
	  File "/home/server/PycharmProjects/sphinx/shared/db_entrust/redis_mode.py", line 176, in insert
[2014-07-17 17:35:44.535760]
ERROR
	    RedisObject.insert(self)
[2014-07-17 17:35:44.535854]
ERROR
	  File "/home/server/PycharmProjects/sphinx/shared/db_entrust/redis_object.py", line 140, in insert
[2014-07-17 17:35:44.535961]
ERROR
	    self._client.mset(newmapping)
[2014-07-17 17:35:44.536048]
ERROR
	  File "build/bdist.linux-x86_64/egg/redis/client.py", line 782, in mset
[2014-07-17 17:35:44.536316]
ERROR
	  File "build/bdist.linux-x86_64/egg/redis/client.py", line 464, in execute_command
[2014-07-17 17:35:44.536540]
ERROR
	  File "build/bdist.linux-x86_64/egg/redis/connection.py", line 334, in send_command
[2014-07-17 17:35:44.536738]
ERROR
	  File "build/bdist.linux-x86_64/egg/redis/connection.py", line 316, in send_packed_command
[2014-07-17 17:35:44.537507]
ERROR
	  File "build/bdist.linux-x86_64/egg/redis/connection.py", line 253, in connect
[2014-07-17 17:35:44.537610]
ERROR
	redis.exceptions.ConnectionError: Error 111 connecting 127.0.0.1:6379. Connection refused.
